Workbook

Sheet predictions_xgb_test
A1: Entry | B1: Organism (ID) | C1: target | D1: proba | E1: pred
A2: A0A5K7RLP0 | B2: 10090 | C2: 1 | D2: 0.9462955 | E2: 1
A3: A2A4P0 | B3: 10090 | C3: 1 | D3: 0.95225275 | E3: 1
A4: A2A9F4 | B4: 10090 | C4: 0 | D4: 0.66923773 | E4: 1
A5: A2AC93 | B5: 10090 | C5: 0 | D5: 0.6676983 | E5: 1
A6: A2AIP0 | B6: 10090 | C6: 0 | D6: 0.7927202 | E6: 1
A7: A2AIW0 | B7: 10090 | C7: 0 | D7: 0.6281908 | E7: 1
A8: A2AJB7 | B8: 10090 | C8: 0 | D8: 0.1537489 | E8: 0
A9: A2AKQ0 | B9: 10090 | C9: 0 | D9: 0.0063556186 | E9: 0
A10: A2ALS5 | B10: 10090 | C10: 0 | D10: 0.3644677 | E10: 0
A11: A2APB8 | B11: 10090 | C11: 1 | D11: 0.9294492 | E11: 1
A12: A2APC3 | B12: 10090 | C12: 0 | D12: 0.20584996 | E12: 0
A13: A2AQ07 | B13: 10090 | C13: 0 | D13: 0.21191475 | E13: 0
... A5541: O89100 | B5541: 10090 | C5541: 1 | D5541: 0.26261467 | E5541: 0
A5542: P00397 | B5542: 10090 | C5542: 0 | D5542: 371.31533 | E5542: 0
A5543: P00520 | B5543: 10090 | C5543: 1 | D5543: 0.84588134 | E5543: 1
A5544: P00687 | B5544: 10090 | C5544: 0 | D5544: 0.023508735 | E5544: 0
A5545: P00796 | B5545: 10090 | C5545: 0 | D5545: 0.057122357 | E5545: 0
A5546: P01108 | B5546: 10090 | C5546: 1 | D5546: 0.9328332 | E5546: 1
A5547: P01572 | B5547: 10090 | C5547: 0 | D5547: 0.17895034 | E5547: 0
A5548: P01590 | B5548: 10090 | C5548: 0 | D5548: 0.57486045 | E5548: 1
A5549: P01592 | B5549: 10090 | C5549: 0 | D5549: 0.2544734 | E5549: 0
A5550: P01731 | B5550: 10090 | C5550: 0 | D5550: 0.06704647 | E5550: 0
A5551: P01898 | B5551: 10090 | C5551: 0 | D5551: 0.02932798 | E5551: 0
A5552: P01910 | B5552: 10090 | C5552: 0 | D5552: 0.10348566 | E5552: 0
A5553: P01921 | B5553: 10090 | C5553: 0 | D5553: 0.078481264 | E5553: 0
A5554: P02535 | B5554: 10090 | C5554: 0 | D5554: 0.068222985 | E5554: 0
A5555: P03911 | B5555: 10090 | C5555: 0 | D5555: 37.50653 | E5555: 0
A5556: P03995 | B5556: 10090 | C5556: 0 | D5556: 0.20978677 | E5556: 0
A5557: P04095 | B5557: 10090 | C5557: 0 | D5557: 0.17153773 | E5557: 0
A5558: P04235 | B5558: 10090 | C5558: 0 | D5558: 0.075642064 | E5558: 0
A5559: P04351 | B5559: 10090 | C5559: 0 | D5559: 0.23555455 | E5559: 0
A5560: P04426 | B5560: 10090 | C5560: 0 | D5560: 0.10421953 | E5560: 0
A5561: P04756 | B5561: 10090 | C5561: 0 | D5561: 0.013408912 | E5561: 0
A5562: P04919 | B5562: 10090 | C5562: 0 | D5562: 0.010109551 | E5562: 0
A5563: P05201 | B5563: 10090 | C5563: 0 | D5563: 0.07379925 | E5563: 0
A5564: P06795 | B5564: 10090 | C5564: 0 | D5564: 0.008938026 | E5564: 0
A5565: P06797 | B5565: 10090 | C5565: 0 | D5565: 0.26184648 | E5565: 0
A5566: P06803 | B5566: 10090 | C5566: 1 | D5566: 0.763604 | E5566: 1
A5567: P06909 | B5567: 10090 | C5567: 0 | D5567: 0.0062689693 | E5567: 0
...

Sheet Graficos
A1: Graficos de Previsao - Modelo XGBoost (conjunto de teste)
A2: Todas as tabelas sao calculadas por formulas a partir da aba predictions_xgb_test (limiar de corte = pred).
A4: 1. Matriz de confusao | B4: Qtd
A5: Verdadeiro Positivo (VP) | B5: =COUNTIFS(predictions_xgb_test!$C$2:$C$33054,1,predictions_xgb_test!$E$2:$E$33054,1) -> 9215
A6: Falso Negativo (FN) | B6: =COUNTIFS(predictions_xgb_test!$C$2:$C$33054,1,predictions_xgb_test!$E$2:$E$33054,0) -> 2079
A7: Falso Positivo (FP) | B7: =COUNTIFS(predictions_xgb_test!$C$2:$C$33054,0,predictions_xgb_test!$E$2:$E$33054,1) -> 3227
A8: Verdadeiro Negativo (VN) | B8: =COUNTIFS(predictions_xgb_test!$C$2:$C$33054,0,predictions_xgb_test!$E$2:$E$33054,0) -> 18532
A9: Total | B9: =SUM(B5:B8) -> 33053
A11: 2. Metricas | B11: Valor
A12: Acuracia | B12: =IFERROR((B5+B8)/B9,"") -> 0.83946994
A13: Precisao | B13: =IFERROR(B5/(B5+B7),"") -> 0.74063655
A14: Recall (Sensibilidade) | B14: =IFERROR(B5/(B5+B6),"") -> 0.81591996
A15: Especificidade | B15: =IFERROR(B8/(B8+B7),"") -> 0.85169355
A16: F1-Score | B16: =IFERROR(2*B13*B14/(B13+B14),"") -> 0.7764577
A18: 3. Faixa de probabilidade | B18: Target = 1 | C18: Target = 0
A19: 0.0 - 0.1 | B19: =COUNTIFS(predictions_xgb_test!$D$2:$D$33054,">=0",predictions_xgb_test!$D$2:$D$33054,"<0.1",predictions_xgb_test!$C$2:$C$33054,1) -> 0 | C19: =COUNTIFS(predictions_xgb_test!$D$2:$D$33054,">=0",predictions_xgb_test!$D$2:$D$33054,"<0.1",predictions_xgb_test!$C$2:$C$33054,0) -> 0
A20: 0.1 - 0.2 | B20: =COUNTIFS(predictions_xgb_test!$D$2:$D$33054,">=0.1",predictions_xgb_test!$D$2:$D$33054,"<0.2",predictions_xgb_test!$C$2:$C$33054,1) -> 321 | C20: =COUNTIFS(predictions_xgb_test!$D$2:$D$33054,">=0.1",predictions_xgb_test!$D$2:$D$33054,"<0.2",predictions_xgb_test!$C$2:$C$33054,0) -> 3472
A21: 0.2 - 0.3 | B21: =COUNTIFS(predictions_xgb_test!$D$2:$D$33054,">=0.2",predictions_xgb_test!$D$2:$D$33054,"<0.3",predictions_xgb_test!$C$2:$C$33054,1) -> 476 | C21: =COUNTIFS(predictions_xgb_test!$D$2:$D$33054,">=0.2",predictions_xgb_test!$D$2:$D$33054,"<0.3",predictions_xgb_test!$C$2:$C$33054,0) -> 2425
A22: 0.3 - 0.4 | B22: =COUNTIFS(predictions_xgb_test!$D$2:$D$33054,">=0.3",predictions_xgb_test!$D$2:$D$33054,"<0.4",predictions_xgb_test!$C$2:$C$33054,1) -> 514 | C22: =COUNTIFS(predictions_xgb_test!$D$2:$D$33054,">=0.3",predictions_xgb_test!$D$2:$D$33054,"<0.4",predictions_xgb_test!$C$2:$C$33054,0) -> 1806
A23: 0.4 - 0.5 | B23: =COUNTIFS(predictions_xgb_test!$D$2:$D$33054,">=0.4",predictions_xgb_test!$D$2:$D$33054,"<0.5",predictions_xgb_test!$C$2:$C$33054,1) -> 672 | C23: =COUNTIFS(predictions_xgb_test!$D$2:$D$33054,">=0.4",predictions_xgb_test!$D$2:$D$33054,"<0.5",predictions_xgb_test!$C$2:$C$33054,0) -> 1430
A24: 0.5 - 0.6 | B24: =COUNTIFS(predictions_xgb_test!$D$2:$D$33054,">=0.5",predictions_xgb_test!$D$2:$D$33054,"<0.6",predictions_xgb_test!$C$2:$C$33054,1) -> 845 | C24: =COUNTIFS(predictions_xgb_test!$D$2:$D$33054,">=0.5",predictions_xgb_test!$D$2:$D$33054,"<0.6",predictions_xgb_test!$C$2:$C$33054,0) -> 1002
A25: 0.6 - 0.7 | B25: =COUNTIFS(predictions_xgb_test!$D$2:$D$33054,">=0.6",predictions_xgb_test!$D$2:$D$33054,"<0.7",predictions_xgb_test!$C$2:$C$33054,1) -> 1127 | C25: =COUNTIFS(predictions_xgb_test!$D$2:$D$33054,">=0.6",predictions_xgb_test!$D$2:$D$33054,"<0.7",predictions_xgb_test!$C$2:$C$33054,0) -> 842
A26: 0.7 - 0.8 | B26: =COUNTIFS(predictions_xgb_test!$D$2:$D$33054,">=0.7",predictions_xgb_test!$D$2:$D$33054,"<0.8",predictions_xgb_test!$C$2:$C$33054,1) -> 1469 | C26: =COUNTIFS(predictions_xgb_test!$D$2:$D$33054,">=0.7",predictions_xgb_test!$D$2:$D$33054,"<0.8",predictions_xgb_test!$C$2:$C$33054,0) -> 568
A27: 0.8 - 0.9 | B27: =COUNTIFS(predictions_xgb_test!$D$2:$D$33054,">=0.8",predictions_xgb_test!$D$2:$D$33054,"<0.9",predictions_xgb_test!$C$2:$C$33054,1) -> 1959 | C27: =COUNTIFS(predictions_xgb_test!$D$2:$D$33054,">=0.8",predictions_xgb_test!$D$2:$D$33054,"<0.9",predictions_xgb_test!$C$2:$C$33054,0) -> 365
A28: 0.9 - 1.0 | B28: =COUNTIFS(predictions_xgb_test!$D$2:$D$33054,">=0.9",predictions_xgb_test!$D$2:$D$33054,"<=1",predictions_xgb_test!$C$2:$C$33054,1) -> 0 | C28: =COUNTIFS(predictions_xgb_test!$D$2:$D$33054,">=0.9",predictions_xgb_test!$D$2:$D$33054,"<=1",predictions_xgb_test!$C$2:$C$33054,0) -> 0
A30: 4. Top 10 organismos (ID) | B30: Positivos reais | C30: Positivos previstos | D30: Total
A31: 10090 | B31: =COUNTIFS(predictions_xgb_test!$B$2:$B$33054,VALUE(A31),predictions_xgb_test!$C$2:$C$33054,1) -> 4481 | C31: =COUNTIFS(predictions_xgb_test!$B$2:$B$33054,VALUE(A31),predictions_xgb_test!$E$2:$E$33054,1) -> 5441 | D31: =COUNTIFS(predictions_xgb_test!$B$2:$B$33054,VALUE(A31)) -> 14039
A32: 284812 | B32: =COUNTIFS(predictions_xgb_test!$B$2:$B$33054,VALUE(A32),predictions_xgb_test!$C$2:$C$33054,1) -> 1894 | C32: =COUNTIFS(predictions_xgb_test!$B$2:$B$33054,VALUE(A32),predictions_xgb_test!$E$2:$E$33054,1) -> 1443 | D32: =COUNTIFS(predictions_xgb_test!$B$2:$B$33054,VALUE(A32)) -> 4097
A33: 8355 | B33: =COUNTIFS(predictions_xgb_test!$B$2:$B$33054,VALUE(A33),predictions_xgb_test!$C$2:$C$33054,1) -> 1441 | C33: =COUNTIFS(predictions_xgb_test!$B$2:$B$33054,VALUE(A33),predictions_xgb_test!$E$2:$E$33054,1) -> 1664 | D33: =COUNTIFS(predictions_xgb_test!$B$2:$B$33054,VALUE(A33)) -> 3056
A34: 8364 | B34: =COUNTIFS(predictions_xgb_test!$B$2:$B$33054,VALUE(A34),predictions_xgb_test!$C$2:$C$33054,1) -> 623 | C34: =COUNTIFS(predictions_xgb_test!$B$2:$B$33054,VALUE(A34),predictions_xgb_test!$E$2:$E$33054,1) -> 754 | D34: =COUNTIFS(predictions_xgb_test!$B$2:$B$33054,VALUE(A34)) -> 1459
A35: 237561 | B35: =COUNTIFS(predictions_xgb_test!$B$2:$B$33054,VALUE(A35),predictions_xgb_test!$C$2:$C$33054,1) -> 377 | C35: =COUNTIFS(predictions_xgb_test!$B$2:$B$33054,VALUE(A35),predictions_xgb_test!$E$2:$E$33054,1) -> 416 | D35: =COUNTIFS(predictions_xgb_test!$B$2:$B$33054,VALUE(A35)) -> 1055
A36: 367110 | B36: =COUNTIFS(predictions_xgb_test!$B$2:$B$33054,VALUE(A36),predictions_xgb_test!$C$2:$C$33054,1) -> 238 | C36: =COUNTIFS(predictions_xgb_test!$B$2:$B$33054,VALUE(A36),predictions_xgb_test!$E$2:$E$33054,1) -> 286 | D36: =COUNTIFS(predictions_xgb_test!$B$2:$B$33054,VALUE(A36)) -> 802
A37: 9986 | B37: =COUNTIFS(predictions_xgb_test!$B$2:$B$33054,VALUE(A37),predictions_xgb_test!$C$2:$C$33054,1) -> 123 | C37: =COUNTIFS(predictions_xgb_test!$B$2:$B$33054,VALUE(A37),predictions_xgb_test!$E$2:$E$33054,1) -> 139 | D37: =COUNTIFS(predictions_xgb_test!$B$2:$B$33054,VALUE(A37)) -> 742
A38: 4081 | B38: =COUNTIFS(predictions_xgb_test!$B$2:$B$33054,VALUE(A38),predictions_xgb_test!$C$2:$C$33054,1) -> 63 | C38: =COUNTIFS(predictions_xgb_test!$B$2:$B$33054,VALUE(A38),predictions_xgb_test!$E$2:$E$33054,1) -> 77 | D38: =COUNTIFS(predictions_xgb_test!$B$2:$B$33054,VALUE(A38)) -> 319
A39: 425011 | B39: =COUNTIFS(predictions_xgb_test!$B$2:$B$33054,VALUE(A39),predictions_xgb_test!$C$2:$C$33054,1) -> 89 | C39: =COUNTIFS(predictions_xgb_test!$B$2:$B$33054,VALUE(A39),predictions_xgb_test!$E$2:$E$33054,1) -> 100 | D39: =COUNTIFS(predictions_xgb_test!$B$2:$B$33054,VALUE(A39)) -> 315
A40: 3055 | B40: =COUNTIFS(predictions_xgb_test!$B$2:$B$33054,VALUE(A40),predictions_xgb_test!$C$2:$C$33054,1) -> 20 | C40: =COUNTIFS(predictions_xgb_test!$B$2:$B$33054,VALUE(A40),predictions_xgb_test!$E$2:$E$33054,1) -> 51 | D40: =COUNTIFS(predictions_xgb_test!$B$2:$B$33054,VALUE(A40)) -> 294
